Workbook

Sheet Portada
A2: Universidad de Cartagena
A3: Centro Tecnológico para la Formación Virtual y a Distancia (CTEV)
A6: Programa | B6: Ingeniería de Software
A7: Asignatura | B7: Probabilidad y Estadística
A8: Código | B8: AF17401
A9: Título | B9: Guía de actividad No 2: Estadística descriptiva
A10: Autor | B10: Jairo Alonso Osorio Cruz
A11: Semestre | B11: VI
A12: Tutor | B12: PENDIENTE: nombre del tutor
A13: Fecha | B13: PENDIENTE: fecha de entrega

Sheet Presentación
A1: Presentación
A3: Este libro de Excel reúne el desarrollo de la Guía de actividad No 2 de Probabilidad y Estadística (AF17401), del programa de Ingeniería de Software de la Universidad de Cartagena. La guía plantea que la Gobernación del Tolima necesita conocer los índices de accidentalidad del departamento, sus posibles causas y sus puntos críticos, y para ello entrega una base con 400 accidentes de tránsito ocurridos en tres municipios.
A5: Este trabajo desarrolla la fase inicial, que consiste en organizar los datos y describirlos. El libro contiene la Tabla 1 con seis conceptos estadísticos, el análisis de la velocidad registrada con su tabla de frecuencia, sus gráficos y sus medidas, y el análisis de la relación entre los años de experiencia del conductor y su histórico de infracciones mediante regresión lineal y correlación de Pearson. Las medidas se calcularon con fórmulas de Excel que apuntan a la hoja de datos incluida en los anexos.

Sheet Introducción
A1: Introducción
A3: El crecimiento de las ciudades y del uso del vehículo automotor ha convertido los accidentes de tránsito en un problema de salud pública: dejan personas fallecidas y heridas, y pérdidas materiales considerables. Para formular soluciones, las autoridades encargadas de las vías y del tránsito necesitan información detallada sobre cuándo, dónde y bajo qué condiciones ocurren los siniestros.
A5: La base de datos del Anexo 1 recoge 400 accidentes en Ibagué (185), Melgar (119) y Espinal (96). Cada registro tiene nueve variables: municipio, edad del conductor, personas fallecidas, personas heridas, velocidad registrada, costo del accidente, nivel educativo, años de experiencia e histórico de infracciones. Al revisarla encontramos 13 parejas de registros idénticos en todas sus columnas. Se conservaron los 400 registros para que el análisis corresponda a la base tal como fue entregada.
A7: La estadística descriptiva resume un conjunto de datos con tablas, gráficos y medidas. Las medidas de tendencia central indican alrededor de qué valores se agrupan los datos, las de posición ubican valores dentro del orden de los datos, las de dispersión muestran qué tan separados están, y las de dependencia lineal miden si dos variables cambian juntas.
A9: El libro sigue el orden de la guía. El ejercicio 1 define seis conceptos con ejemplos de la base, el ejercicio 2 analiza la velocidad registrada y el ejercicio 3 estudia la relación entre años de experiencia e infracciones. Después vienen las conclusiones, la bibliografía y los anexos, que incluyen la hoja de datos, la verificación de los cálculos y las convenciones que adoptamos.

Sheet Objetivos
A1: Objetivos
A3: Objetivo general
A4: Emplear las medidas estadísticas de tendencia central, de dispersión, de posición y de dependencia lineal en la solución de problemas, aplicándolas a la base de datos de accidentalidad del Tolima.
A6: Objetivos específicos
A7: 1. Explicar con palabras propias los conceptos de frecuencia absoluta, frecuencia relativa, media, medidas de dispersión, regresión lineal y correlación de Pearson, con ejemplos tomados de la base de datos.
A8: 2. Organizar la velocidad registrada en una tabla de frecuencia con datos agrupados, representarla con un histograma, un diagrama circular y un polígono de frecuencia, y calcular e interpretar sus medidas de tendencia central, de posición y de dispersión, su asimetría y su curtosis.
A9: 3. Establecer la relación lineal entre los años de experiencia del conductor y el histórico de infracciones mediante la ecuación de regresión, el coeficiente de determinación y el coeficiente de correlación de Pearson, y usar la ecuación para hacer predicciones.

Sheet Ejercicio 1
A1: Ejercicio 1: definiciones de conceptos estadísticos
A3: Tabla 1. Definiciones de conceptos
A4: Conceptos | B4: Definiciones | C4: Ejemplos
A5: Frecuencia absoluta | B5: Es la cantidad de veces que aparece un valor, o un grupo de valores, dentro de los datos. Se obtiene contando, así que siempre es un número entero, y si sumamos las frecuencias de todos los valores obtenemos el total de datos (n). | C5: De los 400 accidentes de la base, 185 ocurrieron en Ibagué, 119 en Melgar y 96 en Espinal. Esos tres números son las frecuencias absolutas del municipio y suman 400.
A6: Frecuencia relativa | B6: Es la parte del total que representa cada valor. Se calcula dividiendo su frecuencia absoluta entre el total de datos y da un número entre 0 y 1, que también se puede escribir como porcentaje. Sirve para comparar grupos sin que importe cuántos datos tenga cada uno, y todas las frecuencias relativas juntas suman 1. | C6: En Ibagué ocurrieron 185 de los 400 accidentes, es decir 185/400 = 0,4625, o sea el 46,25%. Melgar aporta el 29,75% y Espinal el 24%. Por nivel educativo, los conductores bachilleres son 210/400 = 52,5%.
A7: Media | B7: Es el promedio de los datos: sumamos todos los valores y dividimos entre la cantidad de valores. Representa el punto de equilibrio de los datos, por eso un valor muy alejado del resto la mueve con facilidad. Solo se puede calcular con variables numéricas. | C7: Al sumar las velocidades registradas de los 400 accidentes y dividir entre 400 resulta 89,86 km/h, es decir que en promedio el vehículo causante iba casi a 90 km/h. El costo medio por accidente es de 188,21 millones de pesos.
A8: Medidas de dispersión | B8: Indican qué tan juntos o qué tan repartidos están los datos alrededor de su centro. Dos conjuntos pueden tener la misma media y comportarse muy distinto: en uno los datos son parecidos entre sí y en otro están muy dispersos. Las más usadas son el rango (máximo menos mínimo), la varianza, la desviación típica y el coeficiente de variación, que es la desviación dividida entre la media y permite comparar variables con unidades diferentes. | C8: Las velocidades van de 32,1 a 140,8 km/h, así que el rango es de 108,7 km/h. La desviación típica es de 30,39 km/h y el coeficiente de variación de 33,8%, lo que indica que las velocidades se alejan en promedio unos 30 km/h de la media. En cambio, los años de experiencia tienen media de 3,60 y desviación de 3,97, un coeficiente de variación de 110,2%, mucho más disperso en términos relativos.
A9: Regresión lineal | B9: Es una técnica que busca la recta que mejor describe cómo cambia una variable (la dependiente, y) cuando cambia otra (la independiente, x). La recta se escribe y = a + bx: la pendiente b dice cuánto cambia y por cada unidad que aumenta x, y el intercepto a es el valor de y cuando x vale 0. Se ajusta por mínimos cuadrados, de modo que las distancias de los puntos a la recta sean lo más pequeñas posible en conjunto. Sirve para predecir dentro del rango observado, pero por sí sola no demuestra que una variable cause la otra. | C9: Con los años de experiencia (x) y el histórico de infracciones (y) de los 400 conductores, la recta es y = 1,73 + 0,77x. La pendiente indica que por cada año más de experiencia, el modelo asocia unas 0,77 infracciones adicionales en los últimos cinco años.
A10: Correlación de Pearson | B10: Es un número r, entre -1 y 1, que mide qué tan fuerte es la relación lineal entre dos variables numéricas y en qué sentido va. Si r se acerca a 1, cuando una variable sube la otra también; si se acerca a -1, cuando una sube la otra baja; y si está cerca de 0 no hay relación lineal, aunque podría existir otro tipo de relación. No depende de las unidades en que estén medidas las variables, y al elevarlo al cuadrado se obtiene el coeficiente de determinación. | C10: Entre años de experiencia e infracciones, r = 0,77: relación positiva y fuerte. Entre velocidad y costo del accidente, r = 0,04: casi nula, es decir que en esta base ir más rápido no se asocia linealmente con un costo mayor.
A12: Evidencia del quiz
A13: Evidencia del quiz: insertar captura aquí

Sheet Ejercicio 2
A1: Ejercicio 2: estadística descriptiva de la velocidad registrada
A2: Variable elegida: velocidad registrada (km/h), variable cuantitativa continua (columna E de la hoja DATOS, 400 registros).
A4: Tabla de frecuencia con datos agrupados: velocidad registrada (km/h)
A6: Número de datos (n) | B6: =COUNT(DATOS!$E$2:$E$401) -> 400
A7: Valor mínimo | B7: =MIN(DATOS!$E$2:$E$401) -> 32.1
A8: Valor máximo | B8: =MAX(DATOS!$E$2:$E$401) -> 140.8
A9: Rango (R = máximo - mínimo) | B9: =B8-B7 -> 108.7
A10: Número de intervalos (k, regla de Sturges) | B10: =ROUNDUP(1+LOG(B6,2),0) -> 10
A11: Amplitud teórica (R / k) | B11: =B9/B10 -> 10.87
A12: Amplitud adoptada (A), redondeada hacia arriba | B12: 11
A13: Límite inferior del primer intervalo | B13: 32
L14: Auxiliar del polígono (clases vacías en los extremos)
A15: Intervalo | B15: Límite inferior (Li) | C15: Límite superior (Ls) | D15: Marca de clase (xi) | E15: fi | F15: Fi | G15: hi | H15: Hi | I15: hi (%) | J15: Hi (%) | L15: Marca xi | M15: fi
A16: [32 - 43) | B16: =B13 -> 32 | C16: =B16+$B$12 -> 43 | D16: =(B16+C16)/2 -> 37.5 | E16: =COUNTIFS(DATOS!$E$2:$E$401,">="&B16,DATOS!$E$2:$E$401,"<"&C16) -> 34 | F16: =E16 -> 34 | G16: =E16/$B$6 -> 0.085 | H16: =F16/$B$6 -> 0.085 | I16: =G16*100 -> 8.5 | J16: =H16*100 -> 8.5 | L16: =D16-$B$12 -> 26.5 | M16: 0
A17: [43 - 54) | B17: =C16 -> 43 | C17: =B17+$B$12 -> 54 | D17: =(B17+C17)/2 -> 48.5 | E17: =COUNTIFS(DATOS!$E$2:$E$401,">="&B17,DATOS!$E$2:$E$401,"<"&C17) -> 40 | F17: =F16+E17 -> 74 | G17: =E17/$B$6 -> 0.1 | H17: =F17/$B$6 -> 0.185 | I17: =G17*100 -> 10 | J17: =H17*100 -> 18.5 | L17: =D16 -> 37.5 | M17: =E16 -> 34
A18: [54 - 65) | B18: =C17 -> 54 | C18: =B18+$B$12 -> 65 | D18: =(B18+C18)/2 -> 59.5 | E18: =COUNTIFS(DATOS!$E$2:$E$401,">="&B18,DATOS!$E$2:$E$401,"<"&C18) -> 18 | F18: =F17+E18 -> 92 | G18: =E18/$B$6 -> 0.045 | H18: =F18/$B$6 -> 0.23 | I18: =G18*100 -> 4.5 | J18: =H18*100 -> 23 | L18: =D17 -> 48.5 | M18: =E17 -> 40
A19: [65 - 76) | B19: =C18 -> 65 | C19: =B19+$B$12 -> 76 | D19: =(B19+C19)/2 -> 70.5 | E19: =COUNTIFS(DATOS!$E$2:$E$401,">="&B19,DATOS!$E$2:$E$401,"<"&C19) -> 38 | F19: =F18+E19 -> 130 | G19: =E19/$B$6 -> 0.095 | H19: =F19/$B$6 -> 0.325 | I19: =G19*100 -> 9.5 | J19: =H19*100 -> 32.5 | L19: =D18 -> 59.5 | M19: =E18 -> 18
A20: [76 - 87) | B20: =C19 -> 76 | C20: =B20+$B$12 -> 87 | D20: =(B20+C20)/2 -> 81.5 | E20: =COUNTIFS(DATOS!$E$2:$E$401,">="&B20,DATOS!$E$2:$E$401,"<"&C20) -> 40 | F20: =F19+E20 -> 170 | G20: =E20/$B$6 -> 0.1 | H20: =F20/$B$6 -> 0.425 | I20: =G20*100 -> 10 | J20: =H20*100 -> 42.5 | L20: =D19 -> 70.5 | M20: =E19 -> 38
A21: [87 - 98) | B21: =C20 -> 87 | C21: =B21+$B$12 -> 98 | D21: =(B21+C21)/2 -> 92.5 | E21: =COUNTIFS(DATOS!$E$2:$E$401,">="&B21,DATOS!$E$2:$E$401,"<"&C21) -> 50 | F21: =F20+E21 -> 220 | G21: =E21/$B$6 -> 0.125 | H21: =F21/$B$6 -> 0.55 | I21: =G21*100 -> 12.5 | J21: =H21*100 -> 55 | L21: =D20 -> 81.5 | M21: =E20 -> 40
A22: [98 - 109) | B22: =C21 -> 98 | C22: =B22+$B$12 -> 109 | D22: =(B22+C22)/2 -> 103.5 | E22: =COUNTIFS(DATOS!$E$2:$E$401,">="&B22,DATOS!$E$2:$E$401,"<"&C22) -> 48 | F22: =F21+E22 -> 268 | G22: =E22/$B$6 -> 0.12 | H22: =F22/$B$6 -> 0.67 | I22: =G22*100 -> 12 | J22: =H22*100 -> 67 | L22: =D21 -> 92.5 | M22: =E21 -> 50
A23: [109 - 120) | B23: =C22 -> 109 | C23: =B23+$B$12 -> 120 | D23: =(B23+C23)/2 -> 114.5 | E23: =COUNTIFS(DATOS!$E$2:$E$401,">="&B23,DATOS!$E$2:$E$401,"<"&C23) -> 62 | F23: =F22+E23 -> 330 | G23: =E23/$B$6 -> 0.155 | H23: =F23/$B$6 -> 0.825 | I23: =G23*100 -> 15.5 | J23: =H23*100 -> 82.5 | L23: =D22 -> 103.5 | M23: =E22 -> 48
A24: [120 - 131) | B24: =C23 -> 120 | C24: =B24+$B$12 -> 131 | D24: =(B24+C24)/2 -> 125.5 | E24: =COUNTIFS(DATOS!$E$2:$E$401,">="&B24,DATOS!$E$2:$E$401,"<"&C24) -> 34 | F24: =F23+E24 -> 364 | G24: =E24/$B$6 -> 0.085 | H24: =F24/$B$6 -> 0.91 | I24: =G24*100 -> 8.5 | J24: =H24*100 -> 91 | L24: =D23 -> 114.5 | M24: =E23 -> 62
A25: [131 - 142] | B25: =C24 -> 131 | C25: =B25+$B$12 -> 142 | D25: =(B25+C25)/2 -> 136.5 | E25: =COUNTIFS(DATOS!$E$2:$E$401,">="&B25,DATOS!$E$2:$E$401,"<="&C25) -> 36 | F25: =F24+E25 -> 400 | G25: =E25/$B$6 -> 0.09 | H25: =F25/$B$6 -> 1 | I25: =G25*100 -> 9 | J25: =H25*100 -> 100 | L25: =D24 -> 125.5 | M25: =E24 -> 34
A26: Total | E26: =SUM(E16:E25) -> 400 | G26: =SUM(G16:G25) -> 1 | I26: =SUM(I16:I25) -> 100 | L26: =D25 -> 136.5 | M26: =E25 -> 36
L27: =D25+$B$12 -> 147.5 | M27: 0
A28: Los intervalos son cerrados a la izquierda y abiertos a la derecha, salvo el último, que incluye su límite superior.
A29: Gráficos estadísticos y conclusiones
A49: Conclusión del histograma
A50: El intervalo con la barra más alta es [109 - 120) km/h, con 62 accidentes (15,5 %), y el de la barra más baja es [54 - 65) km/h, con solo 18 (4,5 %). Ese valle es un hueco entre dos intervalos vecinos que tienen 40 y 38 accidentes, así que la distribución no es simétrica ni tiene un único pico. Entre 87 y 120 km/h se concentran 160 accidentes (40,0 %), cuatro de cada diez. La base no trae el límite de velocidad de cada vía, por lo que esto muestra dónde se concentran los siniestros y no cuáles velocidades son excesivas.
A73: Conclusión del diagrama circular
A74: Cada porción es el porcentaje de accidentes de un intervalo de velocidad. La más grande es [109 - 120) con 15,5 % y la más pequeña es [54 - 65) con 4,5 %. Como ninguna porción pasa del 15,5 %, ninguna franja de velocidad domina sobre las demás. Los tres intervalos vecinos con más accidentes, de 87 a 120 km/h, suman el 40,0 %. Con diez porciones es difícil comparar tamaños a simple vista, por eso conviene apoyarse en el histograma.
A95: Conclusión del polígono de frecuencia
A96: El polígono une las marcas de clase y se cierra con dos intervalos vacíos, uno antes y otro después (marcas 26,5 y 147,5 km/h), por eso empieza y termina en 0. Arranca en 34 accidentes en la marca 37,5, cae a 18 en la marca 59,5 y desde ese valle sube, con una pequeña baja en 103,5, hasta el pico de 62 en 114,5 km/h. Después baja a 34 y 36. Como el punto medio del rango es 87 km/h y 230 accidentes (57,5 %) se registraron a esa velocidad o más, la distribución se inclina hacia las velocidades altas.
A99: Preguntas con base en la tabla de frecuencia
A101: 1. ¿En cuál intervalo se observa la mayor cantidad de datos?
A102: Intervalo de mayor frecuencia | B102: =INDEX($A$16:$A$25,MATCH(MAX($E$16:$E$25),$E$16:$E$25,0)) -> [109 - 120)
A103: Frecuencia absoluta máxima (fi) | B103: =MAX($E$16:$E$25) -> 62
A104: Porcentaje de los accidentes (hi %) | B104: =INDEX($I$16:$I$25,MATCH(MAX($E$16:$E$25),$E$16:$E$25,0)) -> 15.5
A105: El intervalo con más accidentes es [109 - 120) km/h, con 62 de los 400 registros (15,5 %). Es el intervalo modal de la tabla.
A107: 2. ¿Hasta cuál intervalo se acumula el 60 % de los datos?
...

Sheet Ejercicio 3
A1: Regresión lineal: años de experiencia (x) e histórico de infracciones (y)
A2: Variable independiente (x): años de experiencia del conductor. Variable dependiente (y): número de infracciones en los últimos cinco años.
A4: Datos de partida
A5: Número de pares de datos (n) | B5: =COUNT(DATOS!$H$2:$H$401) -> 400
A6: Media de x (años de experiencia) | B6: =AVERAGE(DATOS!$H$2:$H$401) -> 3.6025
A7: Media de y (infracciones) | B7: =AVERAGE(DATOS!$I$2:$I$401) -> 4.51
A9: Ecuación de regresión lineal (y = a + b x)
A10: Medida | B10: Resultado | C10: Interpretación | J10: Fórmula de Excel
A11: Pendiente (b) | B11: =SLOPE(DATOS!$I$2:$I$401,DATOS!$H$2:$H$401) -> 0.77230382 | C11: Por cada año más de experiencia, el modelo asocia unas 0,77 infracciones adicionales en los últimos cinco años. Esto describe una asociación y no demuestra que la experiencia cause las infracciones. | J11: SLOPE(y, x)
A12: Intercepto (a) | B12: =INTERCEPT(DATOS!$I$2:$I$401,DATOS!$H$2:$H$401) -> 1.7277755 | C12: Es el valor que da la recta para un conductor con 0 años de experiencia: 1,73 infracciones. Ojo: los 53 conductores con 0 años tuvieron en promedio 1,06, así que la recta se aleja algo de los datos en ese extremo. | J12: INTERCEPT(y, x)
A13: Ecuación de la recta | B13: ="y = "&ROUND(B12,4)&IF(B11>=0," + "," - ")&ABS(ROUND(B11,4))&" x" -> y = 1.7278 + 0.7723 x | C13: Es la recta de mínimos cuadrados: con ella se estima el número de infracciones a partir de los años de experiencia. | J13: "y = " & a & " + " & b & " x"
A14: Tipo de relación según la pendiente | B14: =IF(B11>0,"Positiva",IF(B11<0,"Negativa","Sin relación")) -> Positiva | C14: Positiva. La pendiente es mayor que cero y la nube de puntos sube de izquierda a derecha: a más años de experiencia, tienden a ser más las infracciones acumuladas. La fuerza de esa relación se mide con el coeficiente de determinación y con r. | J14: Signo de b
A15: Promedio observado de y con x = 0 | B15: =AVERAGEIF(DATOS!$H$2:$H$401,0,DATOS!$I$2:$I$401) -> 1.0566038 | C15: Se usa para comparar el intercepto de la recta con lo que ocurre realmente en los conductores sin experiencia. | J15: AVERAGEIF(x, 0, y)
A17: Diagrama de dispersión con la recta de regresión
A40: Lectura del diagrama
A41: Positiva. La pendiente es mayor que cero y la nube de puntos sube de izquierda a derecha: a más años de experiencia, tienden a ser más las infracciones acumuladas. La fuerza de esa relación se mide con el coeficiente de determinación y con r. Como las dos variables son números enteros, muchos conductores comparten la misma pareja de valores y sus puntos quedan uno encima de otro. Por eso se ven menos puntos que los 400 registros.
A43: Patrón de los datos
A44: Los datos no forman una nube pareja, sino tres tramos. Con 0 o 1 año de experiencia (118 conductores) las infracciones van de 0 a 2. Con 2 a 10 años (256) van de 2 a 8 y su promedio casi no cambia de un año a otro (entre 4,33 y 6,00). Con 11 años o más (26) van de 10 a 20. La recta resume ese escalón con una sola pendiente, así que sirve como aproximación general pero no describe bien cada tramo por separado.
A47: Coeficiente de determinación, confiabilidad y correlación de Pearson
A49: Medida | B49: Resultado | C49: Interpretación | J49: Fórmula de Excel
A50: Coeficiente de determinación (R²) | B50: =RSQ(DATOS!$I$2:$I$401,DATOS!$H$2:$H$401) -> 0.59662754 | C50: La recta explica el 59,66 % de la variación del número de infracciones a partir de los años de experiencia. El 40,34 % restante depende de otros factores o de variación que la recta no recoge. | J50: RSQ(y, x)
A51: Confiabilidad del modelo (%) | B51: =B50*100 -> 59.662754 | C51: Es el mismo R² expresado en porcentaje: 59,66 %. El modelo da una idea general de cuántas infracciones se esperan según la experiencia, pero deja sin explicar cerca del 40 % de la variación, así que sus predicciones son orientativas y no exactas. | J51: R² x 100
A52: Coeficiente de correlación de Pearson (r) | B52: =CORREL(DATOS!$I$2:$I$401,DATOS!$H$2:$H$401) -> 0.77241669 | C52: Es 0,7724, un valor positivo: al aumentar los años de experiencia tienden a aumentar las infracciones. Elevado al cuadrado da 0,5966, que es el R². | J52: CORREL(y, x)
A53: Nivel de correlación lineal | B53: =IF(ABS(B52)=1,"Perfecta",IF(ABS(B52)>=0.9,"Excelente",IF(ABS(B52)>=0.8,"Aceptable",IF(ABS(B52)>=0.5,"Regular",IF(ABS(B52)>0,"Mínima","Sin correlación"))))) -> Regular | C53: Regular según la escala adoptada (|r| entre 0,50 y 0,80). Como r = 0,77 está cerca del límite de 0,80 que separaría 'aceptable', conviene citar el valor de r junto con la etiqueta. | J53: IF anidado sobre |r|
A55: Escala adoptada para el nivel de correlación (|r|)
A56: Intervalo de |r| | B56: Nivel
A57: |r| = 1 | B57: Perfecta
A58: 0,90 a menos de 1 | B58: Excelente
A59: 0,80 a menos de 0,90 | B59: Aceptable
A60: 0,50 a menos de 0,80 | B60: Regular
A61: Mayor que 0 y menor que 0,50 | B61: Mínima
A62: |r| = 0 | B62: Sin correlación
A64: Esta escala es una convención de uso común que adoptamos en este trabajo. No proviene de las lecturas del curso, y otras escalas usan límites distintos.
A66: Cómo leer estos resultados
A67: Estos valores resumen el ajuste global de la recta. El diagrama mostró tres tramos y, entre 2 y 10 años de experiencia, el promedio de infracciones casi no cambia (entre 4,33 y 6,00), así que un R² de 59,66 % no significa que las infracciones suban de forma continua con cada año. Además, una correlación, por alta que sea, no prueba que la experiencia cause las infracciones.
A69: Predicciones con la ecuación de regresión
A70: La ecuación es y = a + b x, con a y b tomados de las celdas de la pendiente y el intercepto. Las celdas amarillas se pueden cambiar.
A72: Predicción | B72: Experiencia x (años) | C72: Infracciones estimadas ŷ | D72: Promedio observado con ese x | E72: Conductores con ese x | F72: ¿x dentro del rango observado? | G72: Interpretación
A73: Predicción 1 | B73: 1 | C73: =$B$12+$B$11*B73 -> 2.5000793 | D73: =AVERAGEIF(DATOS!$H$2:$H$401,B73,DATOS!$I$2:$I$401) -> 0.50769231 | E73: =COUNTIF(DATOS!$H$2:$H$401,B73) -> 65 | F73: =IF(AND(B73>=MIN(DATOS!$H$2:$H$401),B73<=MAX(DATOS!$H$2:$H$401)),"Sí","No") -> Sí | G73: Para un conductor con 1 año de experiencia, el modelo estima 2,50 infracciones en los últimos cinco años. Los 65 conductores con 1 año tuvieron en promedio 0,51; la estimación queda por encima de lo observado y la recta sobreestima en este tramo.
A74: Predicción 2 | B74: 5 | C74: =$B$12+$B$11*B74 -> 5.5892946 | D74: =AVERAGEIF(DATOS!$H$2:$H$401,B74,DATOS!$I$2:$I$401) -> 5.375 | E74: =COUNTIF(DATOS!$H$2:$H$401,B74) -> 16 | F74: =IF(AND(B74>=MIN(DATOS!$H$2:$H$401),B74<=MAX(DATOS!$H$2:$H$401)),"Sí","No") -> Sí | G74: Para un conductor con 5 años de experiencia, el modelo estima 5,59 infracciones en los últimos cinco años. Los 16 conductores con 5 años tuvieron en promedio 5,38; la estimación coincide bien con lo observado.
...

Sheet Conclusiones
A1: Conclusiones
A3: Ejercicio 1
A4: Las seis definiciones quedaron ilustradas con cifras de la base, lo que permitió ver cada concepto aplicado. Por ejemplo, 185 de los 400 accidentes ocurrieron en Ibagué, es decir el 46,25 %, y las velocidades tienen una desviación típica de 30,39 km/h alrededor de una media de 89,86 km/h. El resultado del quiz de la plataforma se adjunta como evidencia en la hoja del ejercicio 1.
A6: Ejercicio 2
A7: La velocidad registrada tiene una media de 89,86 km/h, una mediana de 94,05 km/h y valores entre 32,1 y 140,8 km/h. El intervalo con más accidentes es [109 - 120) km/h, con 62 registros (15,5 %), y el 60 % de los accidentes se acumula hasta el intervalo [98 - 109) km/h. La mitad central de los accidentes ocurrió entre 66,25 y 114,85 km/h, y el 20 % más rápido superó los 117,98 km/h. Con un coeficiente de variación de 33,82 % la distribución es heterogénea según la convención adoptada, y con una asimetría de -0,26 y una curtosis de -1,00 resulta casi simétrica y platicúrtica: las velocidades se extienden por todo el rango sin concentrarse alrededor de un valor.
A9: Ejercicio 3
A10: La recta de regresión entre los años de experiencia (x) y las infracciones (y) es y = 1,7278 + 0,7723 x, con una relación positiva. El coeficiente de determinación es 0,5966 (59,66 %) y el coeficiente de correlación de Pearson es 0,7724, un nivel regular de correlación lineal según la escala adoptada, cerca del límite con el nivel aceptable. El diagrama de dispersión muestra tres tramos de experiencia, por lo que la recta sirve como aproximación general: con 5 años estima 5,59 infracciones y el promedio observado es 5,38, pero con 12 años estima 11,00 frente a 15,50 observadas. El error típico de la estimación es de 2,52 infracciones, así que las predicciones son orientativas.
A12: Conclusión general
A13: En esta base la velocidad se reparte a lo largo de un rango amplio, con el 45 % de los accidentes a 98 km/h o más, y los conductores con más años de licencia tienden a acumular más infracciones. Estos resultados describen los datos y no explican causas: la base no trae el límite de velocidad de cada vía, y una correlación no prueba que una variable produzca la otra. Los umbrales de homogeneidad, asimetría y correlación son convenciones que adoptamos y se declaran donde se usan.

Sheet Bibliografía
A1: Bibliografía
A3: Romero Ramos, E. (2016). Estadística para todos: análisis de datos: estadística descriptiva, teoría de la probabilidad e inferencia. Difusora Larousse - Ediciones Pirámide. https://elibro.unicartagenaproxy.elogim.com/es/lc/unicartagena/titulos/49136
A5: Salazar Guerrero, L. J. (2018). Probabilidad y estadística: para bachilleratos tecnológicos. Grupo Editorial Patria. https://elibro.unicartagenaproxy.elogim.com/es/lc/unicartagena/titulos/40531

Sheet Anexos
A1: Anexos
A3: Anexo A. Hoja de datos
A4: Copia exacta, sin modificar ningún valor, de la hoja DATOS del Anexo 1: 400 registros y 9 columnas. Es la hoja a la que apuntan todas las fórmulas del libro.
A5: La base contiene 13 parejas de registros idénticos en las nueve columnas. Están en las filas 213 y 313, 214 y 314, 220 y 320, 221 y 321, 227 y 327, 237 y 337, 240 y 340, 241 y 341, 246 y 346, 269 y 369, 285 y 385, 300 y 400, 301 y 401 de la hoja (numeración de Excel, con el encabezado en la fila 1). Cada pareja está separada exactamente por 100 filas. Se conservaron todos los registros.
A7: Anexo B. Verificación de los cálculos
A8: Se compararon 141 valores del libro con cálculos independientes hechos en Python (numpy y scipy) a partir de los datos originales, y con el recálculo de las fórmulas de Excel en LibreOffice. Todos coincidieron, con una diferencia absoluta máxima de 5,7e-13. La tabla lista cada comparación.
A9: Las tablas, los gráficos y las fórmulas del libro se generaron con un programa en Python (biblioteca xlsxwriter) que escribe fórmulas nativas de Excel.
A11: Ejercicio | B11: Bloque | C11: Medida | D11: Valor en Excel (recalculado) | E11: Valor en Python | F11: Diferencia | G11: Resultado
A12: Ejercicio 2 | B12: Tabla de frecuencia | C12: Tabla, intervalo 1: Li | D12: 32 | E12: 32 | F12: 0 | G12: Coincide
A13: Ejercicio 2 | B13: Tabla de frecuencia | C13: Tabla, intervalo 2: Li | D13: 43 | E13: 43 | F13: 0 | G13: Coincide
A14: Ejercicio 2 | B14: Tabla de frecuencia | C14: Tabla, intervalo 3: Li | D14: 54 | E14: 54 | F14: 0 | G14: Coincide
A15: Ejercicio 2 | B15: Tabla de frecuencia | C15: Tabla, intervalo 4: Li | D15: 65 | E15: 65 | F15: 0 | G15: Coincide
A16: Ejercicio 2 | B16: Tabla de frecuencia | C16: Tabla, intervalo 5: Li | D16: 76 | E16: 76 | F16: 0 | G16: Coincide
A17: Ejercicio 2 | B17: Tabla de frecuencia | C17: Tabla, intervalo 6: Li | D17: 87 | E17: 87 | F17: 0 | G17: Coincide
A18: Ejercicio 2 | B18: Tabla de frecuencia | C18: Tabla, intervalo 7: Li | D18: 98 | E18: 98 | F18: 0 | G18: Coincide
A19: Ejercicio 2 | B19: Tabla de frecuencia | C19: Tabla, intervalo 8: Li | D19: 109 | E19: 109 | F19: 0 | G19: Coincide
A20: Ejercicio 2 | B20: Tabla de frecuencia | C20: Tabla, intervalo 9: Li | D20: 120 | E20: 120 | F20: 0 | G20: Coincide
A21: Ejercicio 2 | B21: Tabla de frecuencia | C21: Tabla, intervalo 10: Li | D21: 131 | E21: 131 | F21: 0 | G21: Coincide
A22: Ejercicio 2 | B22: Tabla de frecuencia | C22: Tabla, intervalo 1: Ls | D22: 43 | E22: 43 | F22: 0 | G22: Coincide
A23: Ejercicio 2 | B23: Tabla de frecuencia | C23: Tabla, intervalo 2: Ls | D23: 54 | E23: 54 | F23: 0 | G23: Coincide
... A107: Ejercicio 2 | B107: Parámetros de la tabla | C107: Parámetro R/k | D107: 10.87 | E107: 10.87 | F107: 1.7763568e-15 | G107: Coincide
A108: Ejercicio 2 | B108: Preguntas | C108: Intervalo de mayor frecuencia | D108: [109 - 120) | E108: [109 - 120) | F108: 0 | G108: Coincide
A109: Ejercicio 2 | B109: Preguntas | C109: Frecuencia absoluta máxima (fi) | D109: 62 | E109: 62 | F109: 0 | G109: Coincide
A110: Ejercicio 2 | B110: Preguntas | C110: Porcentaje de los accidentes (hi %) | D110: 15.5 | E110: 15.5 | F110: 0 | G110: Coincide
A111: Ejercicio 2 | B111: Preguntas | C111: Intervalo donde se alcanza el 60 % | D111: [98 - 109) | E111: [98 - 109) | F111: 0 | G111: Coincide
A112: Ejercicio 2 | B112: Preguntas | C112: Hi (%) del intervalo anterior | D112: 55 | E112: 55 | F112: 7.1054274e-15 | G112: Coincide
A113: Ejercicio 2 | B113: Preguntas | C113: Hi (%) del intervalo donde se alcanza | D113: 67 | E113: 67 | F113: 0 | G113: Coincide
A114: Ejercicio 2 | B114: Preguntas | C114: Estimación dentro del intervalo (km/h) | D114: 102.58333 | E114: 102.58333 | F114: 3.2684966e-13 | G114: Coincide
A115: Ejercicio 2 | B115: Tendencia central y posición | C115: Moda | D115: 81.6 | E115: 81.6 | F115: 0 | G115: Coincide
A116: Ejercicio 2 | B116: Tendencia central y posición | C116: Media | D116: 89.8615 | E116: 89.8615 | F116: 1.4210855e-14 | G116: Coincide
A117: Ejercicio 2 | B117: Tendencia central y posición | C117: Mediana | D117: 94.05 | E117: 94.05 | F117: 0 | G117: Coincide
A118: Ejercicio 2 | B118: Tendencia central y posición | C118: Mínimo | D118: 32.1 | E118: 32.1 | F118: 0 | G118: Coincide
A119: Ejercicio 2 | B119: Tendencia central y posición | C119: Máximo | D119: 140.8 | E119: 140.8 | F119: 0 | G119: Coincide
A120: Ejercicio 2 | B120: Tendencia central y posición | C120: Rango | D120: 108.7 | E120: 108.7 | F120: 1.4210855e-14 | G120: Coincide
A121: Ejercicio 2 | B121: Tendencia central y posición | C121: Cuartil 1 (Q1) | D121: 66.25 | E121: 66.25 | F121: 0 | G121: Coincide
A122: Ejercicio 2 | B122: Tendencia central y posición | C122: Decil 5 (D5) | D122: 94.05 | E122: 94.05 | F122: 0 | G122: Coincide
A123: Ejercicio 2 | B123: Tendencia central y posición | C123: Cuartil 3 (Q3) | D123: 114.85 | E123: 114.85 | F123: 0 | G123: Coincide
... A132: Ejercicio 3 | B132: Regresión lineal | C132: Intercepto (a) | D132: 1.7277755 | E132: 1.7277755 | F132: 2.8865799e-15 | G132: Coincide
A133: Ejercicio 3 | B133: Regresión lineal | C133: Ecuación | D133: y = 1.7278 + 0.7723 x | E133: y = 1.7278 + 0.7723 x | F133: 0 | G133: Coincide
A134: Ejercicio 3 | B134: Regresión lineal | C134: Tipo de relación | D134: Positiva | E134: Positiva | F134: 0 | G134: Coincide
...

Sheet DATOS
A1: MUNICIPIO DEL SINIESTRO | B1: EDAD CONDUCTOR | C1: NÚMERO DE PERSONAS FALLECIDAS | D1: NÚMERO DE PERSONAS HERIDAS | E1: VELOCIDAD REGISTRADA (km/H) | F1: COSTO ACCIDENTE (MILLONES DE PESOS) | G1: NIVEL EDUCATIVO DEL CONDUCTOR | H1: AÑOS DE EXPERIENCIA DEL CONDUCTOR | I1: HISTÓRICO DE INFRACCIONES
A2: Melgar | B2: 20 | C2: 3 | D2: 2 | E2: 75.5 | F2: 243 | G2: Superior | H2: 1 | I2: 1
A3: Ibagué | B3: 30 | C3: 4 | D3: 4 | E3: 34.6 | F3: 39.2 | G3: Bachiller | H3: 5 | I3: 6
A4: Espinal | B4: 26 | C4: 1 | D4: 4 | E4: 76.4 | F4: 270.5 | G4: Bachiller | H4: 3 | I4: 3
A5: Espinal | B5: 25 | C5: 0 | D5: 6 | E5: 56.8 | F5: 196.2 | G5: Bachiller | H5: 2 | I5: 8
A6: Ibagué | B6: 48 | C6: 4 | D6: 3 | E6: 82.8 | F6: 273.6 | G6: Superior | H6: 2 | I6: 3
A7: Espinal | B7: 22 | C7: 4 | D7: 3 | E7: 115.9 | F7: 363.7 | G7: Bachiller | H7: 5 | I7: 6
A8: Espinal | B8: 32 | C8: 0 | D8: 1 | E8: 66.1 | F8: 262.5 | G8: Bachiller | H8: 5 | I8: 7
A9: Ibagué | B9: 21 | C9: 3 | D9: 1 | E9: 110.6 | F9: 314.9 | G9: Superior | H9: 5 | I9: 5
A10: Melgar | B10: 39 | C10: 0 | D10: 3 | E10: 93 | F10: 340 | G10: Bachiller | H10: 6 | I10: 8
A11: Ibagué | B11: 39 | C11: 2 | D11: 3 | E11: 44.9 | F11: 168.8 | G11: Bachiller | H11: 6 | I11: 7
A12: Espinal | B12: 28 | C12: 3 | D12: 5 | E12: 54 | F12: 191.1 | G12: Superior | H12: 4 | I12: 7
A13: Ibagué | B13: 38 | C13: 1 | D13: 5 | E13: 33.9 | F13: 227.7 | G13: Superior | H13: 3 | I13: 3
... A401: Melgar | B401: 32 | C401: 3 | D401: 1 | E401: 41.2 | F401: 221 | G401: Bachiller | H401: 4 | I401: 6
